Traceback (most recent call last):
  File "/usr/local/lib/python3.12/dist-packages/jupyter_cache/executors/utils.py", line 58, in single_nb_execution
    executenb(
  File "/usr/local/lib/python3.12/dist-packages/nbclient/client.py", line 1204, in execute
    return NotebookClient(nb=nb, resources=resources, km=km, **kwargs).execute()
           ^^^^^^^^^^^^^^^^^^^^^^^^^^^^^^^^^^^^^^^^^^^^^^^^^^^^^^^^^^^^^^^^^^^^^
  File "/usr/local/lib/python3.12/dist-packages/nbclient/util.py", line 84, in wrapped
    return just_run(coro(*args, **kwargs))
           ^^^^^^^^^^^^^^^^^^^^^^^^^^^^^^^
  File "/usr/local/lib/python3.12/dist-packages/nbclient/util.py", line 62, in just_run
    return loop.run_until_complete(coro)
           ^^^^^^^^^^^^^^^^^^^^^^^^^^^^^
  File "/usr/lib/python3.12/asyncio/base_events.py", line 687, in run_until_complete
    return future.result()
           ^^^^^^^^^^^^^^^
  File "/usr/local/lib/python3.12/dist-packages/nbclient/client.py", line 663, in async_execute
    await self.async_execute_cell(
  File "/usr/local/lib/python3.12/dist-packages/nbclient/client.py", line 965, in async_execute_cell
    await self._check_raise_for_error(cell, cell_index, exec_reply)
  File "/usr/local/lib/python3.12/dist-packages/nbclient/client.py", line 862, in _check_raise_for_error
    raise CellExecutionError.from_cell_and_msg(cell, exec_reply_content)
nbclient.exceptions.CellExecutionError: An error occurred while executing the following cell:
------------------
System.out.println("Wat is de leeftijd van de kat, in mensenjaren?");
System.out.println();
System.out.print("Leeftijd van de kat (in jaren) ?");
Scanner s = new Scanner(System.in);
int leeftijdkat=s.nextInt();
int leeftijdkat_mensenjaren=leeftijdKatNaarMens(leeftijdkat);
System.out.println("De leeftijd van de kat in mensenjaren is "+leeftijdkat_mensenjaren+" jaar.");
------------------

java.base/java.util.Scanner.throwFor(Scanner.java:937)
java.base/java.util.Scanner.next(Scanner.java:1594)
java.base/java.util.Scanner.nextInt(Scanner.java:2258)
java.base/java.util.Scanner.nextInt(Scanner.java:2212)
.(#47:1)
EvalException: null

